{"name": "test_login", "status": "broken", "statusDetails": {"message": "Exception: 登录出现异常了", "trace": "self = <test_cases.test_1.TestApi object at 0x1062a4690>\n\n>   ???\nE   Exception: 登录出现异常了\n\n/Users/wang/PycharmProjects/Web_AutoTest/test_cases/test_1.py:25: Exception"}, "start": 1742820491183, "stop": 1742820491183, "uuid": "fd63809b-9758-48b5-ae0a-f38974f68b89", "historyId": "d474bed6b24ad1ff6443a8783d04346e", "testCaseId": "d474bed6b24ad1ff6443a8783d04346e", "fullName": "test_cases.test_1.TestApi#test_login", "labels": [{"name": "feature", "value": "模块名称：用户管理模块"}, {"name": "epic", "value": "项目名称：奥里给科技自动化测试报告"}, {"name": "story", "value": "接口名称：登录接口"}, {"name": "parentSuite", "value": "test_cases"}, {"name": "suite", "value": "test_1"}, {"name": "subSuite", "value": "TestApi"}, {"name": "host", "value": "WangdeMac-mini.local"}, {"name": "thread", "value": "39436-MainThread"}, {"name": "framework", "value": "pytest"}, {"name": "language", "value": "cpython3"}, {"name": "package", "value": "test_cases.test_1"}]}